{"active":1705361414043,"date":1705361389010,"event":"draft","input":"<span class=\"user-mention\" account-id=openai-gpt-3.5-turbo >@GPT-3.5</span> help me fix my code.\n\n<details><summary>Context</summary>\n\n\nI ran a cell in a Sage Worksheet.\n\nI received the following error:\n\n```sage\nError in lines 1-1\nTraceback (most recent call last):\n  File \"/cocalc/lib/python3.11/site-packages/smc_sagews/sage_server.py\", line 1245, in execute\n    compile(block + '\\n',\n  File \"<string>\", line 1\n    Chapter Integer(2): Euclidian Space\n            ^^^^^^^\nSyntaxError: invalid syntax\n\n```\nMy SageMath Worksheet contains:\n\n```sage\nChapter 2: Euclidian Space\n```\n</details>\n\n","sender_id":"a7f1627e-1407-4622-bf78-0b469fd1450a"}
{"active":1705977955203,"date":0,"event":"draft","input":" ","sender_id":"a7f1627e-1407-4622-bf78-0b469fd1450a"}
{"date":"2024-01-15T23:29:49.010Z","editing":{"a7f1627e-1407-4622-bf78-0b469fd1450a":"FUTURE"},"event":"chat","history":[{"author_id":"a7f1627e-1407-4622-bf78-0b469fd1450a","content":"<span class=\"user-mention\" account-id=openai-gpt-3.5-turbo >@GPT-3.5</span> help me fix my code.\n\n<details><summary>Context</summary>\n\n\nI ran a cell in a Sage Worksheet.\n\nI received the following error:\n\n```sage\nError in lines 1-1\nTraceback (most recent call last):\n  File \"/cocalc/lib/python3.11/site-packages/smc_sagews/sage_server.py\", line 1245, in execute\n    compile(block + '\\n',\n  File \"<string>\", line 1\n    Chapter Integer(2): Euclidian Space\n            ^^^^^^^\nSyntaxError: invalid syntax\n\n```\n\n\nMy SageMath Worksheet contains:\n\n```sage\nChapter 2: Euclidian Space\n```\n\n\n\n</details>","date":"2024-01-15T23:29:49.010Z"}],"sender_id":"a7f1627e-1407-4622-bf78-0b469fd1450a"}
{"date":"2024-01-15T23:29:49.026Z","event":"chat","generating":false,"history":[{"author_id":"openai-gpt-3.5-turbo","content":"The error message suggests that there is a syntax error in code. In SageMath, you cannot use numbers directly as variable names. To fix the issue, you can enclose the chapter title in quotes to treat it as a string instead. Here is the corrected code:\n\n```sage\nChapter = \"2: Euclidian Space\"\n``Make sure to run the corrected code and check if it produces the desired output.","date":"2024-01-15T23:29:49.026Z"}],"reply_to":"2024-01-15T23:29:49.010Z","sender_id":"openai-gpt-3.5-turbo"}
{"date":"2024-01-16T01:01:45.915Z","event":"chat","history":[{"author_id":"a7f1627e-1407-4622-bf78-0b469fd1450a","content":"<span class=\"user-mention\" account-id=openai-gpt-3.5-turbo >@GPT-3.5</span> help me fix my code.\n\n<details><summary>Context</summary>\n\n\nI ran a cell in a Sage Worksheet.\n\nI received the following error:\n\n```sage\n/ext/sage/10.2/local/var/lib/sage/venv-python3.11.1/lib/python3.11/site-packages/scikits/__init__.py:1: DeprecationWarning: pkg_resources is deprecated as an API. See https://setuptools.pypa.io/en/latest/pkg_resources.html\n  __import__(\"pkg_resources\").declare_namespace(__name__)\n/ext/sage/10.2/local/var/lib/sage/venv-python3.11.1/lib/python3.11/site-packages/scikits/__init__.py:1: DeprecationWarning: Deprecated call to `pkg_resources.declare_namespace('scikits')`.\nImplementing implicit namespace packages (as specified in PEP 420) is preferred to `pkg_resources.declare_namespace`. See https://setuptools.pypa.io/en/latest/references/keywords.html#keyword-namespace-packages\n  __import__(\"pkg_resources\").declare_namespace(__name__)\n\n```\n\n\nMy SageMath Worksheet contains:\n\n```sage\narrow((0,0,0), (1,1,1))\n```\n\n\n\n</details>","date":"2024-01-16T01:01:45.915Z"}],"sender_id":"a7f1627e-1407-4622-bf78-0b469fd1450a"}
{"date":"2024-01-16T01:01:45.921Z","event":"chat","generating":false,"history":[{"author_id":"openai-gpt-3.5-turbo","content":"It seems like you are encountering a `DeprecationWarning` when running your code in a Sage Worksheet. The warning is related to the `scikits` package and the use of `pkg_resources`. \n\nTo fix this issue, you can try the following steps:\n\n1. Import the `warnings` module at the beginning of your code:\n\n```sage\nimport warnings\n```\n\n2. Use the `warnings.filterwarnings()` function to filter out the specific warning:\n\n```sage\nwarnings.filterwarnings(\"ignore\", category=DeprecationWarning)\n```\n\n3. Run your code as usual:\n\n```sage\narrow((0,0,0), (1,1,1))\n```\n\nThese steps should suppress the `DeprecationWarning` and allow your code to run without displaying the warning message.","date":"2024-01-16T01:01:45.921Z"}],"reply_to":"2024-01-16T01:01:45.915Z","sender_id":"openai-gpt-3.5-turbo"}
{"date":"2024-01-23T02:45:33.005Z","event":"chat","history":[{"author_id":"a7f1627e-1407-4622-bf78-0b469fd1450a","content":"<span class=\"user-mention\" account-id=openai-gpt-3.5-turbo >@GPT-3.5</span> help me fix my code.\n\n<details><summary>Context</summary>\n\n\nI ran a cell in a Sage Worksheet.\n\nI received the following error:\n\n```sage\nError in lines 4-4\nTraceback (most recent call last):\n  File \"/cocalc/lib/python3.11/site-packages/smc_sagews/sage_server.py\", line 1244, in execute\n    exec(\n  File \"\", line 1, in <module>\n  File \"sage/modules/free_module_element.pyx\", line 587, in sage.modules.free_module_element.vector\n    v, R = prepare(v, R, degree)\n  File \"sage/modules/free_module_element.pyx\", line 687, in sage.modules.free_module_element.prepare\n    v = Sequence(v, universe=R, use_sage_types=True)\n  File \"/ext/sage/10.2/src/sage/structure/sequence.py\", line 232, in Sequence\n    x = list(x)  # make a copy even if x is a list, we're going to change it\n        ^^^^^^^\nTypeError: 'sage.symbolic.expression.Expression' object is not iterable\n\n```\n\n\nMy SageMath Worksheet contains:\n\n```sage\nx, y, z = var(\"x y z\")\nA = matrix([[1, -2, 0], [3,1,-2]]);\nAtrans = A.transpose()\nxVect = vector(x, y, z)\nb = vector([6, 16, 0])\nprint(Atrans, xVect, \" = \", b)\n\nprint()\nnumOfrows = len(Atrans.rows()); \nnumOfcols = len(Atrans.colums()); \n# for i in range(numOfrows):\n#     equation = \"\"\n#     for j in range(numOfcols):\n#         equation = equation + (A[j][i] * xVect[i]) + \" + \"\n        \n#     print(equation, \" = \", b[i])\n```\n\n\n\n</details>","date":"2024-01-23T02:45:33.005Z"}],"sender_id":"a7f1627e-1407-4622-bf78-0b469fd1450a"}
{"date":"2024-01-23T02:45:33.011Z","event":"chat","generating":false,"history":[{"author_id":"openai-gpt-3.5-turbo","content":"The error message indicates that there is a problem with the line: \n\n```sage\nnumOfcols = len(Atrans.colums());\n```\n\nThe error is in the spelling of `columns`. You have misspelled it as `colums`.\n\nTo fix the error, change the line to:\n\n```sage\nnumOfcols = len(Atrans.columns());\n```\n\nAfter making this change, re-run the cell and the error should be resolved.","date":"2024-01-23T02:45:33.011Z"}],"reply_to":"2024-01-23T02:45:33.005Z","sender_id":"openai-gpt-3.5-turbo"}
{"date":"2024-01-23T02:45:55.526Z","event":"chat","history":[{"author_id":"a7f1627e-1407-4622-bf78-0b469fd1450a","content":"<span class=\"user-mention\" account-id=openai-gpt-3.5-turbo >@GPT-3.5</span> help me fix my code.\n\n<details><summary>Context</summary>\n\n\nI ran a cell in a Sage Worksheet.\n\nI received the following error:\n\n```sage\nError in lines 4-4\nTraceback (most recent call last):\n  File \"/cocalc/lib/python3.11/site-packages/smc_sagews/sage_server.py\", line 1244, in execute\n    exec(\n  File \"\", line 1, in <module>\n  File \"sage/modules/free_module_element.pyx\", line 587, in sage.modules.free_module_element.vector\n    v, R = prepare(v, R, degree)\n  File \"sage/modules/free_module_element.pyx\", line 687, in sage.modules.free_module_element.prepare\n    v = Sequence(v, universe=R, use_sage_types=True)\n  File \"/ext/sage/10.2/src/sage/structure/sequence.py\", line 232, in Sequence\n    x = list(x)  # make a copy even if x is a list, we're going to change it\n        ^^^^^^^\nTypeError: 'sage.symbolic.expression.Expression' object is not iterable\n\n```\n\n\nMy SageMath Worksheet contains:\n\n```sage\nx, y, z = var(\"x y z\")\nA = matrix([[1, -2, 0], [3,1,-2]]);\nAtrans = A.transpose()\nxVect = vector(x, y, z)\nb = vector([6, 16, 0])\nprint(Atrans, xVect, \" = \", b)\n\nprint()\nnumOfrows = len(Atrans.rows()); \nnumOfcols = len(Atrans.columns()); \n# for i in range(numOfrows):\n#     equation = \"\"\n#     for j in range(numOfcols):\n#         equation = equation + (A[j][i] * xVect[i]) + \" + \"\n        \n#     print(equation, \" = \", b[i])\n```\n\n\n\n</details>","date":"2024-01-23T02:45:55.526Z"}],"sender_id":"a7f1627e-1407-4622-bf78-0b469fd1450a"}
{"date":"2024-01-23T02:45:55.532Z","event":"chat","generating":false,"history":[{"author_id":"openai-gpt-3.5-turbo","content":"The error you are encountering is a \"TypeError: 'sage.symbolic.expression.Expression' object is not iterable\". This suggests that there is an issue with using the `A[j][i]` syntax to access elements of the matrix `A`.\n\nTo fix this, you can use the `A.get(j, i)` method instead of `A[j][i]`. Here's the updated code:\n\n```sage\nx, y, z = var(\"x y z\")\nA = matrix([[1, -2, 0], [3,1,-2]]);\nAtrans = A.transpose()\nxVect = vector(x, y, z)\nb = vector([6, 16, 0])\nprint(Atrans, xVect, \" = \", b)\n\nprint()\nnumOfrows = len(Atrans.rows())\nnumOfcols = len(Atrans.columns())\n\nfor i in range(numOfrows):\n    equation = \"\"\n    for j in range(numOfcols):\n        equation = equation + (A.get(j, i) * xVect[i]) + \" + \"\n        \n    print(equation, \" = \", b[i])\n```","date":"2024-01-23T02:45:55.532Z"}],"reply_to":"2024-01-23T02:45:55.526Z","sender_id":"openai-gpt-3.5-turbo"}